<sdf version='1.7'>
  <model name='door2'>
    <link name="outward">
      <virtual_volume name="outward_vv">
        <geometry>
          <box>
            <size>0.2 0.35 0.01</size>
          </box>
        </geometry>
        <pose>0.6 0.6 0.0 0 0 0</pose>
      </virtual_volume>
    </link>
    <link name="inward">
      <virtual_volume name="inward_vv">
        <geometry>
          <box>
            <size>0.2 0.35 0.01</size>
          </box>
        </geometry>
        <pose>-0.6 0.6 0.0 0 0 0</pose>
      </virtual_volume>
    </link>
    <link name='door_frame'>
      <inertial>
        <pose>-3.2e-05 0.57447 0.83303 0 -0 0</pose>
        <mass>51.073</mass>
        <inertia>
          <ixx>50.017</ixx>
          <ixy>-0.00079296</ixy>
          <ixz>0.00067786</ixz>
          <iyy>38.461</iyy>
          <iyz>0.01138</iyz>
          <izz>15.722</izz>
        </inertia>
      </inertial>
      <collision name='door_frame_collision'>
        <pose>0 0 0 0 -0 0</pose>
        <geometry>
          <mesh>
            <scale>1 1 1</scale>
            <uri>model://door2/meshes/door_frame.STL</uri>
          </mesh>
        </geometry>
      </collision>
      <visual name='door_frame_visual'>
        <pose>0 0 0 0 -0 0</pose>
        <geometry>
          <mesh>
            <scale>1 1 1</scale>
            <uri>model://door2/meshes/door_frame.STL</uri>
          </mesh>
        </geometry>
        <material>
          <script>
            <uri>model://door2/scripts</uri>
            <uri>model://door2/textures</uri>
            <name>Door/WhiteWood</name>
          </script>
        </material>
      </visual>
    </link>
    <joint name='rot_plate' type='revolute'>
      <pose relative_to='door_frame'>-0.032 0.1 1.94 -9.3e-05 -1.57079 3.14159</pose>
      <parent>door_frame</parent>
      <child>door_plate</child>
      <axis>
        <xyz>1 0 0</xyz>
        <limit>
          <lower>-0.1</lower>
          <upper>1.57</upper>
          <effort>0</effort>
          <velocity>0</velocity>
        </limit>
        <dynamics>
          <damping>0.1</damping>
          <friction>1</friction>
          <spring_reference>0</spring_reference>
          <spring_stiffness>0</spring_stiffness>
        </dynamics>
      </axis>
    </joint>
    <link name='door_plate'>
      <pose relative_to='rot_plate'>0 0 0 0 -0 0</pose>
      <inertial>
        <pose>-0.688441 -0.483512 0.021993 0 -0 0</pose>
        <mass>7.26871</mass>
        <inertia>
          <ixx>0.557484</ixx>
          <ixy>-0.00198187</ixy>
          <ixz>3.00585e-05</ixz>
          <iyy>3.64988</iyy>
          <iyz>0.000243064</iyz>
          <izz>4.20619</izz>
        </inertia>
      </inertial>
      <collision name='door_plate_collision'>
        <pose>0 0 0 0 -0 0</pose>
        <geometry>
          <mesh>
            <scale>1 1 1</scale>
            <uri>model://door2/meshes/door_plate.STL</uri>
          </mesh>
        </geometry>
      </collision>
      <collision name='door_plate_fixed_joint_lump__door_locker_collision_1'>
        <pose>-0.69495 -0.865 0.042 3.1415 -1.5708 0</pose>
        <geometry>
          <mesh>
            <scale>1 1 1</scale>
            <uri>model://door2/meshes/door_locker.STL</uri>
          </mesh>
        </geometry>
      </collision>
      <visual name='door_plate_visual'>
        <pose>0 0 0 0 -0 0</pose>
        <geometry>
          <mesh>
            <scale>1 1 1</scale>
            <uri>model://door2/meshes/door_plate.STL</uri>
          </mesh>
        </geometry>
        <material>
          <script>
            <uri>model://door2/scripts</uri>
            <uri>model://door2/textures</uri>
            <name>Door/WhiteWood</name>
          </script>
        </material>
      </visual>
      <visual name='door_plate_fixed_joint_lump__door_locker_visual_1'>
        <pose>-0.69495 -0.865 0.042 3.1415 -1.5708 0</pose>
        <geometry>
          <mesh>
            <scale>1 1 1</scale>
            <uri>model://door2/meshes/door_locker.STL</uri>
          </mesh>
        </geometry>
        <material>
          <script>
            <uri>model://door2/scripts</uri>
            <uri>model://door2/textures</uri>
            <name>Handle/GrayMetal</name>
          </script>
        </material>
      </visual>
    </link>
    <joint name='rot_handle' type='revolute'>
      <pose relative_to='door_plate'>-0.69495 -0.865 0.042 3.14141 -1.57079 -3.14159</pose>
      <parent>door_plate</parent>
      <child>door_handle</child>
      <axis>
        <xyz>1 0 0</xyz>
        <limit>
          <lower>-0.1</lower>
          <upper>1.57</upper>
          <effort>0</effort>
          <velocity>0</velocity>
        </limit>
        <dynamics>
          <damping>0.1</damping>
          <friction>1</friction>
          <spring_reference>0</spring_reference>
          <spring_stiffness>0</spring_stiffness>
        </dynamics>
      </axis>
    </joint>
    <link name='door_handle'>
      <virtual_volume name="handle_vv">
        <geometry>
          <box>
            <size>0.2 0.12 0.12</size>
          </box>
        </geometry>
        <pose>0 0.965 1.26 0 0 0</pose>
      </virtual_volume>
      <pose relative_to='rot_handle'>0 0 0 0 -0 0</pose>
      <inertial>
        <pose>-0.02 0.023356 -0 0 -0 0</pose>
        <mass>0.046826</mass>
        <inertia>
          <ixx>4.8725e-05</ixx>
          <ixy>3.3286e-19</ixy>
          <ixz>4.449e-19</ixz>
          <iyy>0.0001374</iyy>
          <iyz>1.7087e-19</iyz>
          <izz>0.00018447</izz>
        </inertia>
      </inertial>
      <collision name='door_handle_collision'>
        <pose>0 0 0 0 -0 0</pose>
        <geometry>
          <mesh>
            <scale>1 1 1</scale>
            <uri>model://door2/meshes/door_handle.STL</uri>
          </mesh>
        </geometry>
      </collision>
      <visual name='door_handle_visual'>
        <pose>0 0 0 0 -0 0</pose>
        <geometry>
          <mesh>
            <scale>1 1 1</scale>
            <uri>model://door2/meshes/door_handle.STL</uri>
          </mesh>
        </geometry>
        <material>
          <script>
            <uri>model://door2/scripts</uri>
            <uri>model://door2/textures</uri>
            <name>Handle/GrayMetal</name>
          </script>
        </material>
      </visual>
    </link>
  </model>
</sdf>
