<?xml version="1.0"?>
<sdf version="1.6">
  <model name="sergio">
    <link name="base">
      <pose relative_to="">0 0 0 0 -0 0</pose>
      <inertial>
        <pose relative_to="">-0.01024 -0 0.17701 0 -0 0</pose>
        <mass>1.54</mass>
        <inertia>
          <ixx>0.0277523</ixx>
          <ixy>7.67365e-19</ixy>
          <ixz>0.0304456</ixz>
          <iyy>0.126132</iyy>
          <iyz>-3.19223e-19</iyz>
          <izz>0.127502</izz>
        </inertia>
      </inertial>
      <collision name="base_link_collision">
        <pose relative_to="">0 0 0 0 -0 0</pose>
        <geometry>
          <cylinder>
            <length>0</length>
            <radius>0</radius>
          </cylinder>
        </geometry>
      </collision>
      <collision name="base_link_fixed_joint_lump__base_collision_1">
        <pose relative_to="">-0.02 0 0.07 0 -0 0</pose>
        <geometry>
          <box>
            <size>0.73 0.65 0.14</size>
          </box>
        </geometry>
      </collision>
      <collision name="base_link_fixed_joint_lump__back_laser_mount_collision_2">
        <pose relative_to="">-0.293 0 0.237 0 -0 0</pose>
        <geometry>
          <box>
            <size>0.06 0.28 0.01</size>
          </box>
        </geometry>
      </collision>
      <collision name="base_link_fixed_joint_lump__back_laser_collision_3">
        <pose relative_to="">-0.293 0 0.276 0 -0 3.14159</pose>
        <geometry>
          <box>
            <size>0.06 0.06 0.069</size>
          </box>
        </geometry>
      </collision>
      <collision name="base_link_fixed_joint_lump__back_lasertop_collision_4">
        <pose relative_to="">-0.293 0 0.3195 0 -0 3.14159</pose>
        <geometry>
          <box>
            <size>0.06 0.06 0.018</size>
          </box>
        </geometry>
      </collision>
      <collision name="base_link_fixed_joint_lump__base_torso_mount_collision_5">
        <pose relative_to="">0 0 0.095 0 -0 0</pose>
        <geometry>
          <cylinder>
            <length>0</length>
            <radius>0</radius>
          </cylinder>
        </geometry>
      </collision>
      <collision name="base_link_fixed_joint_lump__torso_mounting_frame_collision_6">
        <pose relative_to="">0 0 0.17 0 -0 0</pose>
        <geometry>
          <box>
            <size>0.5 0.4 0.05</size>
          </box>
        </geometry>
      </collision>
      <collision name="base_link_fixed_joint_lump__laser_mount_collision_7">
        <pose relative_to="">0.3045 -0 0.1065 3.14159 -0 0</pose>
        <geometry>
          <box>
            <size>0.01 0.06 0.035</size>
          </box>
        </geometry>
      </collision>
      <collision name="base_link_fixed_joint_lump__base_laser_collision_8">
        <pose relative_to="">0.3295 -0 0.09 3.14159 -0 0</pose>
        <geometry>
          <box>
            <size>0.06 0.06 0.069</size>
          </box>
        </geometry>
      </collision>
      <collision name="base_link_fixed_joint_lump__base_lasertop_collision_9">
        <pose relative_to="">0.3295 -0 0.0465 3.14159 -0 0</pose>
        <geometry>
          <box>
            <size>0.06 0.06 0.018</size>
          </box>
        </geometry>
      </collision>
      <collision name="base_link_fixed_joint_lump__sidepot_back_collision_10">
        <pose relative_to="">-0.305 0 0.195 0 -0 0</pose>
        <geometry>
          <box>
            <size>0.16 0.65 0.13</size>
          </box>
        </geometry>
      </collision>
      <collision name="base_link_fixed_joint_lump__sidepot_left_collision_11">
        <pose relative_to="">-0.01 0.2425 0.195 0 -0 0</pose>
        <geometry>
          <box>
            <size>0.43 0.165 0.13</size>
          </box>
        </geometry>
      </collision>
      <collision name="base_link_fixed_joint_lump__sidepot_right_collision_12">
        <pose relative_to="">-0.01 -0.2425 0.195 0 -0 0</pose>
        <geometry>
          <box>
            <size>0.43 0.165 0.13</size>
          </box>
        </geometry>
      </collision>
      <visual name="base_link_visual">
        <pose relative_to="">0 0 0 0 -0 0</pose>
        <geometry>
          <cylinder>
            <length>0</length>
            <radius>0</radius>
          </cylinder>
        </geometry>
      </visual>
      <visual name="base_link_fixed_joint_lump__base_visual_1">
        <pose relative_to="">-0.02 0 0.07 0 -0 0</pose>
        <geometry>
          <box>
            <size>0.73 0.65 0.14</size>
          </box>
        </geometry>
      </visual>
      <visual name="base_link_fixed_joint_lump__back_laser_mount_visual_2">
        <pose relative_to="">-0.293 0 0.237 0 -0 0</pose>
        <geometry>
          <box>
            <size>0.06 0.28 0.01</size>
          </box>
        </geometry>
      </visual>
      <visual name="base_link_fixed_joint_lump__back_laser_visual_3">
        <pose relative_to="">-0.293 0 0.276 0 -0 3.14159</pose>
        <geometry>
          <box>
            <size>0.06 0.06 0.069</size>
          </box>
        </geometry>
      </visual>
      <visual name="base_link_fixed_joint_lump__back_lasertop_visual_4">
        <pose relative_to="">-0.293 0 0.3195 0 -0 3.14159</pose>
        <geometry>
          <box>
            <size>0.06 0.06 0.018</size>
          </box>
        </geometry>
      </visual>
      <visual name="base_link_fixed_joint_lump__base_torso_mount_visual_5">
        <pose relative_to="">0 0 0.095 0 -0 0</pose>
        <geometry>
          <cylinder>
            <length>0</length>
            <radius>0</radius>
          </cylinder>
        </geometry>
      </visual>
      <visual name="base_link_fixed_joint_lump__torso_mounting_frame_visual_6">
        <pose relative_to="">0 0 0.17 0 -0 0</pose>
        <geometry>
          <box>
            <size>0.5 0.4 0.05</size>
          </box>
        </geometry>
      </visual>
      <visual name="base_link_fixed_joint_lump__laser_mount_visual_7">
        <pose relative_to="">0.3045 -0 0.1065 3.14159 -0 0</pose>
        <geometry>
          <box>
            <size>0.01 0.06 0.035</size>
          </box>
        </geometry>
      </visual>
      <visual name="base_link_fixed_joint_lump__base_laser_visual_8">
        <pose relative_to="">0.3295 -0 0.09 3.14159 -0 0</pose>
        <geometry>
          <box>
            <size>0.06 0.06 0.069</size>
          </box>
        </geometry>
      </visual>
      <visual name="base_link_fixed_joint_lump__base_lasertop_visual_9">
        <pose relative_to="">0.3295 -0 0.0465 3.14159 -0 0</pose>
        <geometry>
          <box>
            <size>0.06 0.06 0.018</size>
          </box>
        </geometry>
      </visual>
      <visual name="base_link_fixed_joint_lump__sidepot_back_visual_10">
        <pose relative_to="">-0.305 0 0.195 0 -0 0</pose>
        <geometry>
          <box>
            <size>0.16 0.65 0.13</size>
          </box>
        </geometry>
      </visual>
      <visual name="base_link_fixed_joint_lump__sidepot_left_visual_11">
        <pose relative_to="">-0.01 0.2425 0.195 0 -0 0</pose>
        <geometry>
          <box>
            <size>0.43 0.165 0.13</size>
          </box>
        </geometry>
      </visual>
      <visual name="base_link_fixed_joint_lump__sidepot_right_visual_12">
        <pose relative_to="">-0.01 -0.2425 0.195 0 -0 0</pose>
        <geometry>
          <box>
            <size>0.43 0.165 0.13</size>
          </box>
        </geometry>
      </visual>
    </link>
    <link name="lower_rear_leg">
      <pose relative_to="">-0.185 0 0.2015 0 -0 0</pose>
      <inertial>
        <pose relative_to="">0.195 0 0 0 -0 0</pose>
        <mass>5</mass>
        <inertia>
          <ixx>0.001</ixx>
          <ixy>0</ixy>
          <ixz>0</ixz>
          <iyy>0.001</iyy>
          <iyz>0</iyz>
          <izz>0.001</izz>
        </inertia>
      </inertial>
      <collision name="lower_rear_leg_collision">
        <pose relative_to="">0.195 0 0 0 -0 0</pose>
        <geometry>
          <box>
            <size>0.39 0.2 0.05</size>
          </box>
        </geometry>
      </collision>
      <visual name="lower_rear_leg_visual">
        <pose relative_to="">0.195 0 0 0 -0 0</pose>
        <geometry>
          <box>
            <size>0.39 0.2 0.05</size>
          </box>
        </geometry>
      </visual>
    </link>
    <joint name="ankle_joint" type="revolute">
      <child>lower_rear_leg</child>
      <parent>base_link</parent>
      <axis>
        <xyz expressed_in="__model__">0 -1 0</xyz>
        <limit>
          <lower>0.152</lower>
          <upper>1</upper>
          <effort>1000</effort>
          <velocity>0.265</velocity>
        </limit>
        <dynamics>
          <damping>6</damping>
          <friction>4.87</friction>
          <spring_reference>0</spring_reference>
          <spring_stiffness>0</spring_stiffness>
        </dynamics>
      </axis>
    </joint>
    <link name="upper_leg">
      <pose relative_to="">0.205 0 0.2015 -0.001593 0.001593 3.14159</pose>
      <inertial>
        <pose relative_to="">0.20575 0 0 0 -0 0</pose>
        <mass>5</mass>
        <inertia>
          <ixx>0.001</ixx>
          <ixy>0</ixy>
          <ixz>0</ixz>
          <iyy>0.001</iyy>
          <iyz>0</iyz>
          <izz>0.001</izz>
        </inertia>
      </inertial>
      <collision name="upper_leg_collision">
        <pose relative_to="">0.20575 0 0 0 -0 0</pose>
        <geometry>
          <box>
            <size>0.4115 0.2 0.1</size>
          </box>
        </geometry>
      </collision>
      <visual name="upper_leg_visual">
        <pose relative_to="">0.20575 0 0 0 -0 0</pose>
        <geometry>
          <box>
            <size>0.4115 0.2 0.1</size>
          </box>
        </geometry>
      </visual>
    </link>
    <joint name="knee_joint" type="revolute">
      <child>upper_leg</child>
      <parent>lower_rear_leg</parent>
      <axis>
        <xyz expressed_in="__model__">-3e-06 0.999999 0.001593</xyz>
        <limit>
          <lower>0.419</lower>
          <upper>2.059</upper>
          <effort>1000</effort>
          <velocity>0.539</velocity>
        </limit>
        <dynamics>
          <damping>6</damping>
          <friction>4.87</friction>
          <spring_reference>0</spring_reference>
          <spring_stiffness>0</spring_stiffness>
        </dynamics>
      </axis>
    </joint>
    <link name="trunk">
      <pose relative_to="">-0.206499 -0 0.200845 -0 -0 3e-06</pose>
      <inertial>
        <pose relative_to="">0.243359 0 -3.3e-05 0 -0 0</pose>
        <mass>10.35</mass>
        <inertia>
          <ixx>0.0223699</ixx>
          <ixy>0</ixy>
          <ixz>0.000107463</ixz>
          <iyy>0.0420765</iyy>
          <iyz>-4.81381e-06</iyz>
          <izz>0.0433416</izz>
        </inertia>
      </inertial>
      <collision name="trunk_collision">
        <pose relative_to="">0.235 0 0 0 -0 0</pose>
        <geometry>
          <box>
            <size>0.47 0.2 0.15</size>
          </box>
        </geometry>
      </collision>
      <collision name="trunk_fixed_joint_lump__head_mount_collision_1">
        <pose relative_to="">0.555307 0 -0.00689 3.14 0.065 0</pose>
        <geometry>
          <box>
            <size>0.061 0.08 0.08</size>
          </box>
        </geometry>
      </collision>
      <collision name="trunk_fixed_joint_lump__shoulder_mount_left_collision_2">
        <pose relative_to="">0.47 0.065 0.000247 -1.57319 -0 0</pose>
        <geometry>
          <cylinder>
            <length>0.14</length>
            <radius>0.075</radius>
          </cylinder>
        </geometry>
      </collision>
      <collision name="trunk_fixed_joint_lump__shoulder_mount_right_collision_3">
        <pose relative_to="">0.47 -0.065 -0.000247 -1.57319 -0 0</pose>
        <geometry>
          <cylinder>
            <length>0.14</length>
            <radius>0.075</radius>
          </cylinder>
        </geometry>
      </collision>
      <visual name="trunk_visual">
        <pose relative_to="">0.235 0 0 0 -0 0</pose>
        <geometry>
          <box>
            <size>0.47 0.2 0.15</size>
          </box>
        </geometry>
      </visual>
      <visual name="trunk_fixed_joint_lump__head_mount_visual_1">
        <pose relative_to="">0.555307 0 -0.00689 3.14 0.065 0</pose>
        <geometry>
          <box>
            <size>0.061 0.08 0.08</size>
          </box>
        </geometry>
      </visual>
      <visual name="trunk_fixed_joint_lump__shoulder_mount_left_visual_2">
        <pose relative_to="">0.47 0.065 0.000247 -1.57319 -0 0</pose>
        <geometry>
          <cylinder>
            <length>0.14</length>
            <radius>0.075</radius>
          </cylinder>
        </geometry>
      </visual>
      <visual name="trunk_fixed_joint_lump__shoulder_mount_right_visual_3">
        <pose relative_to="">0.47 -0.065 -0.000247 -1.57319 -0 0</pose>
        <geometry>
          <cylinder>
            <length>0.14</length>
            <radius>0.075</radius>
          </cylinder>
        </geometry>
      </visual>
    </link>
    <joint name="hip_joint" type="revolute">
      <child>trunk</child>
      <parent>upper_leg</parent>
      <axis>
        <xyz expressed_in="__model__">3e-06 -1 0</xyz>
        <limit>
          <lower>1.007</lower>
          <upper>2.31</upper>
          <effort>1000</effort>
          <velocity>0.375</velocity>
        </limit>
        <dynamics>
          <damping>6</damping>
          <friction>4.87</friction>
          <spring_reference>0</spring_reference>
          <spring_stiffness>0</spring_stiffness>
        </dynamics>
      </axis>
    </joint>
    <link name="neck_pan">
      <pose relative_to="">0.399201 2e-06 0.190675 -3.11872 1.50577 -3.11708</pose>
      <inertial>
        <pose relative_to="">0 0 -0.01 0 -0 0</pose>
        <mass>0.05</mass>
        <inertia>
          <ixx>0.0001</ixx>
          <ixy>0</ixy>
          <ixz>0</ixz>
          <iyy>0.0001</iyy>
          <iyz>0</iyz>
          <izz>0.0001</izz>
        </inertia>
      </inertial>
      <collision name="neck_pan_collision">
        <pose relative_to="">0 0 -0.01 0 -0 0</pose>
        <geometry>
          <cylinder>
            <length>0.02</length>
            <radius>0.015</radius>
          </cylinder>
        </geometry>
      </collision>
      <visual name="neck_pan_visual">
        <pose relative_to="">0 0 -0.01 0 -0 0</pose>
        <geometry>
          <cylinder>
            <length>0.02</length>
            <radius>0.015</radius>
          </cylinder>
        </geometry>
      </visual>
    </link>
    <joint name="neck_pan_joint" type="revolute">
      <child>neck_pan</child>
      <parent>trunk</parent>
      <axis>
        <xyz expressed_in="__model__">0.997887 0.001595 -0.06496</xyz>
        <limit>
          <lower>-1.586</lower>
          <upper>1.586</upper>
          <effort>13.4</effort>
          <velocity>1</velocity>
        </limit>
        <dynamics>
          <damping>0.1</damping>
          <friction>0</friction>
          <spring_reference>0</spring_reference>
          <spring_stiffness>0</spring_stiffness>
        </dynamics>
      </axis>
    </joint>
    <link name="neck_tilt">
      <pose relative_to="">0.399201 2e-06 0.190675 -3.11872 1.50577 -3.11708</pose>
      <inertial>
        <pose relative_to="">0.009452 0.002575 0.029027 0 -0 0</pose>
        <mass>0.073</mass>
        <inertia>
          <ixx>0.00332243</ixx>
          <ixy>-3.86301e-06</ixy>
          <ixz>-1.65411e-05</ixz>
          <iyy>0.00333348</iyy>
          <iyz>-4.50685e-06</iyz>
          <izz>0.00331731</izz>
        </inertia>
      </inertial>
      <collision name="neck_tilt_collision">
        <pose relative_to="">0 -0 0.018 0 -0 0</pose>
        <geometry>
          <box>
            <size>0.03 0.03 0.036</size>
          </box>
        </geometry>
      </collision>
      <collision name="neck_tilt_fixed_joint_lump__head_collision_1">
        <pose relative_to="">0 0 0.177 0 0 -1.5708</pose>
        <geometry>
          <box>
            <size>0.001 0.001 0.001</size>
          </box>
        </geometry>
      </collision>
      <visual name="neck_tilt_visual">
        <pose relative_to="">0 -0 0.018 0 -0 0</pose>
        <geometry>
          <box>
            <size>0.03 0.03 0.036</size>
          </box>
        </geometry>
      </visual>
      <visual name="neck_tilt_fixed_joint_lump__head_visual_1">
        <pose relative_to="">0 0 0.177 0 0 -1.5708</pose>
        <geometry>
          <box>
            <size>0.001 0.001 0.001</size>
          </box>
        </geometry>
      </visual>
      <visual name="neck_tilt_fixed_joint_lump__top_kinect/openni_camera_visual_2">
        <pose relative_to="">0.03 0 0.053 0 -0 0</pose>
        <geometry>
          <mesh>
            <scale>1 1 1</scale>
            <uri>model://sergio_description/media/meshes/kinect_without_base.dae</uri>
          </mesh>
        </geometry>
      </visual>
    </link>
    <joint name="neck_tilt_joint" type="revolute">
      <child>neck_tilt</child>
      <parent>neck_pan</parent>
      <axis>
        <xyz expressed_in="__model__">-0.001695 0.999997 -0.001486</xyz>
        <limit>
          <lower>-0.994</lower>
          <upper>0.994</upper>
          <effort>13.4</effort>
          <velocity>1</velocity>
        </limit>
        <dynamics>
          <damping>0.1</damping>
          <friction>0</friction>
          <spring_reference>0</spring_reference>
          <spring_stiffness>0</spring_stiffness>
        </dynamics>
      </axis>
    </joint>
    <link name="torso_laser_mount">
      <pose relative_to="">0.100801 1e-06 0.113745 3.14 1.406 3e-06</pose>
      <inertial>
        <pose relative_to="">0 0 -0.028587 0 -0 0</pose>
        <mass>0.52</mass>
        <inertia>
          <ixx>0.000326884</ixx>
          <ixy>0</ixy>
          <ixz>0</ixz>
          <iyy>0.000326884</iyy>
          <iyz>0</iyz>
          <izz>0.0003</izz>
        </inertia>
      </inertial>
      <collision name="torso_laser_mount_collision">
        <pose relative_to="">0 0 0 0 -0 0</pose>
        <geometry>
          <box>
            <size>0 0 0</size>
          </box>
        </geometry>
      </collision>
      <collision name="torso_laser_mount_fixed_joint_lump__torso_laser_collision_1">
        <pose relative_to="">0 0 -0.03 0 -0 0</pose>
        <geometry>
          <box>
            <size>0.06 0.06 0.069</size>
          </box>
        </geometry>
      </collision>
      <collision name="torso_laser_mount_fixed_joint_lump__torso_lasertop_collision_2">
        <pose relative_to="">0 0 0.0135 0 -0 0</pose>
        <geometry>
          <box>
            <size>0.06 0.06 0.018</size>
          </box>
        </geometry>
      </collision>
      <visual name="torso_laser_mount_visual">
        <pose relative_to="">0 0 0 0 -0 0</pose>
        <geometry>
          <box>
            <size>0 0 0</size>
          </box>
        </geometry>
      </visual>
      <visual name="torso_laser_mount_fixed_joint_lump__torso_laser_visual_1">
        <pose relative_to="">0 0 -0.03 0 -0 0</pose>
        <geometry>
          <box>
            <size>0.06 0.06 0.069</size>
          </box>
        </geometry>
      </visual>
      <visual name="torso_laser_mount_fixed_joint_lump__torso_lasertop_visual_2">
        <pose relative_to="">0 0 0.0135 0 -0 0</pose>
        <geometry>
          <box>
            <size>0.06 0.06 0.018</size>
          </box>
        </geometry>
      </visual>
    </link>
    <joint name="laser_tilt_joint" type="revolute">
      <child>torso_laser_mount</child>
      <parent>trunk</parent>
      <axis>
        <xyz expressed_in="__model__">0.001574 -0.999999 0.000261</xyz>
        <limit>
          <lower>0</lower>
          <upper>0.324</upper>
          <effort>13.4</effort>
          <velocity>1</velocity>
        </limit>
        <dynamics>
          <damping>0.1</damping>
          <friction>0</friction>
          <spring_reference>0</spring_reference>
          <spring_stiffness>0</spring_stiffness>
        </dynamics>
      </axis>
    </joint>
    <link name="shoulder_link1_left">
      <pose relative_to="">0.2635 0.220001 0.200845 -0.002309 1.5692 -1.5731</pose>
      <inertial>
        <pose relative_to="">0 0 0 0 -0 0</pose>
        <mass>0.25</mass>
        <inertia>
          <ixx>6</ixx>
          <ixy>0</ixy>
          <ixz>0</ixz>
          <iyy>0.01</iyy>
          <iyz>0</iyz>
          <izz>0.01</izz>
        </inertia>
      </inertial>
      <collision name="shoulder_link1_left_collision">
        <pose relative_to="">0 0 -0.0525 0 -0 0</pose>
        <geometry>
          <cylinder>
            <length>0.015</length>
            <radius>0.045</radius>
          </cylinder>
        </geometry>
      </collision>
      <visual name="shoulder_link1_left_visual">
        <pose relative_to="">0 0 -0.0525 0 -0 0</pose>
        <geometry>
          <cylinder>
            <length>0.015</length>
            <radius>0.045</radius>
          </cylinder>
        </geometry>
      </visual>
    </link>
    <joint name="shoulder_yaw_joint_left" type="revolute">
      <child>shoulder_link1_left</child>
      <parent>trunk</parent>
      <axis>
        <xyz expressed_in="__model__">4e-06 0.001593 0.999999</xyz>
        <limit>
          <lower>-1.57</lower>
          <upper>0</upper>
          <effort>13.4</effort>
          <velocity>1</velocity>
        </limit>
        <dynamics>
          <damping>4</damping>
          <friction>4.87</friction>
          <spring_reference>0</spring_reference>
          <spring_stiffness>0</spring_stiffness>
        </dynamics>
      </axis>
    </joint>
    <link name="shoulder_link2_left">
      <pose relative_to="">0.2635 0.220001 0.200845 -1.57311 1.5692 -1.5731</pose>
      <inertial>
        <pose relative_to="">0 0 0 0 -0 0</pose>
        <mass>0.15</mass>
        <inertia>
          <ixx>0.01</ixx>
          <ixy>0</ixy>
          <ixz>0</ixz>
          <iyy>4.04</iyy>
          <iyz>0</iyz>
          <izz>0.001</izz>
        </inertia>
      </inertial>
      <collision name="shoulder_link2_left_collision">
        <pose relative_to="">0 0.06 -0.05 0 -0 0</pose>
        <geometry>
          <box>
            <size>0.035 0.01 0.1</size>
          </box>
        </geometry>
      </collision>
      <visual name="shoulder_link2_left_visual">
        <pose relative_to="">0 0.06 -0.05 0 -0 0</pose>
        <geometry>
          <box>
            <size>0.035 0.01 0.1</size>
          </box>
        </geometry>
      </visual>
    </link>
    <joint name="shoulder_pitch_joint_left" type="revolute">
      <child>shoulder_link2_left</child>
      <parent>shoulder_link1_left</parent>
      <axis>
        <xyz expressed_in="__model__">1e-05 -0.999999 0.001593</xyz>
        <limit>
          <lower>-1.57</lower>
          <upper>1.57</upper>
          <effort>13.4</effort>
          <velocity>1</velocity>
        </limit>
        <dynamics>
          <damping>4</damping>
          <friction>6.06</friction>
          <spring_reference>0</spring_reference>
          <spring_stiffness>0</spring_stiffness>
        </dynamics>
      </axis>
    </joint>
    <link name="upper_arm_left">
      <pose relative_to="">0.2635 0.220001 0.200845 -0.002309 1.5692 -1.5731</pose>
      <inertial>
        <pose relative_to="">0 -0.2 0 0 -0 0</pose>
        <mass>2.95</mass>
        <inertia>
          <ixx>0.027</ixx>
          <ixy>0</ixy>
          <ixz>0</ixz>
          <iyy>0.45993</iyy>
          <iyz>0</iyz>
          <izz>0.004</izz>
        </inertia>
      </inertial>
      <collision name="upper_arm_left_collision">
        <pose relative_to="">-0.00959 -0.19131 -1e-05 0 -0 3.1415</pose>
        <geometry>
          <mesh>
            <scale>0.0004 0.0004 0.0004</scale>
            <uri>model://sergio_description/media/meshes/upperarmtextured.dae</uri>
          </mesh>
        </geometry>
      </collision>
      <visual name="upper_arm_left_visual">
        <pose relative_to="">-0.00959 -0.19131 -1e-05 0 -0 3.1415</pose>
        <geometry>
          <mesh>
            <scale>0.0004 0.0004 0.0004</scale>
            <uri>model://sergio_description/media/meshes/upperarmtextured.dae</uri>
          </mesh>
        </geometry>
      </visual>
    </link>
    <joint name="shoulder_roll_joint_left" type="revolute">
      <child>upper_arm_left</child>
      <parent>shoulder_link2_left</parent>
      <axis>
        <xyz expressed_in="__model__">-1 -6e-06 4e-06</xyz>
        <limit>
          <lower>-1.57</lower>
          <upper>1.57</upper>
          <effort>9.8</effort>
          <velocity>1</velocity>
        </limit>
        <dynamics>
          <damping>3.8</damping>
          <friction>2.216</friction>
          <spring_reference>0</spring_reference>
          <spring_stiffness>0</spring_stiffness>
        </dynamics>
      </axis>
    </joint>
    <link name="elbow_link4_left">
      <pose relative_to="">-0.0565 0.219983 0.190846 -1.57311 1.5692 -1.5731</pose>
      <inertial>
        <pose relative_to="">0 0 0 0 -0 0</pose>
        <mass>0.1</mass>
        <inertia>
          <ixx>0.001</ixx>
          <ixy>0</ixy>
          <ixz>0</ixz>
          <iyy>0.6</iyy>
          <iyz>0</iyz>
          <izz>0.001</izz>
        </inertia>
      </inertial>
      <collision name="elbow_link4_left_collision">
        <pose relative_to="">0 0 0 0 -0 0</pose>
        <geometry>
          <cylinder>
            <length>0</length>
            <radius>0</radius>
          </cylinder>
        </geometry>
      </collision>
      <visual name="elbow_link4_left_visual">
        <pose relative_to="">0 0 0 0 -0 0</pose>
        <geometry>
          <cylinder>
            <length>0</length>
            <radius>0</radius>
          </cylinder>
        </geometry>
      </visual>
    </link>
    <joint name="elbow_pitch_joint_left" type="revolute">
      <child>elbow_link4_left</child>
      <parent>upper_arm_left</parent>
      <axis>
        <xyz expressed_in="__model__">1e-05 -0.999999 0.001593</xyz>
        <limit>
          <lower>0</lower>
          <upper>2.23</upper>
          <effort>4.5</effort>
          <velocity>1</velocity>
        </limit>
        <dynamics>
          <damping>3</damping>
          <friction>1.18</friction>
          <spring_reference>0</spring_reference>
          <spring_stiffness>0</spring_stiffness>
        </dynamics>
      </axis>
    </joint>
    <link name="fore_arm_left">
      <pose relative_to="">-0.0565 0.219983 0.190846 -0.002309 1.5692 -1.5731</pose>
      <inertial>
        <pose relative_to="">0 -0.14 0 0 -0 0</pose>
        <mass>0.85</mass>
        <inertia>
          <ixx>0.001</ixx>
          <ixy>0</ixy>
          <ixz>0</ixz>
          <iyy>0.5</iyy>
          <iyz>0</iyz>
          <izz>0.001</izz>
        </inertia>
      </inertial>
      <collision name="fore_arm_left_collision">
        <pose relative_to="">0.00425 -0.14868 0.00547 3.14159 -1.57079 3.14159</pose>
        <geometry>
          <mesh>
            <scale>0.0004 0.0004 0.0004</scale>
            <uri>model://sergio_description/media/meshes/forearmtextured.dae</uri>
          </mesh>
        </geometry>
      </collision>
      <visual name="fore_arm_left_visual">
        <pose relative_to="">0.00425 -0.14868 0.00547 3.14159 -1.57079 3.14159</pose>
        <geometry>
          <mesh>
            <scale>0.0004 0.0004 0.0004</scale>
            <uri>model://sergio_description/media/meshes/forearmtextured.dae</uri>
          </mesh>
        </geometry>
      </visual>
    </link>
    <joint name="elbow_roll_joint_left" type="revolute">
      <child>fore_arm_left</child>
      <parent>elbow_link4_left</parent>
      <axis>
        <xyz expressed_in="__model__">-1 -6e-06 4e-06</xyz>
        <limit>
          <lower>-1.83</lower>
          <upper>1.83</upper>
          <effort>4.5</effort>
          <velocity>1</velocity>
        </limit>
        <dynamics>
          <damping>3.5</damping>
          <friction>1.35</friction>
          <spring_reference>0</spring_reference>
          <spring_stiffness>0</spring_stiffness>
        </dynamics>
      </axis>
    </joint>
    <link name="wrist_link6_left">
      <pose relative_to="">-0.3365 0.219966 0.180847 -3.14 -7e-06 -3.14159</pose>
      <inertial>
        <pose relative_to="">0 0 0 0 -0 0</pose>
        <mass>0.01</mass>
        <inertia>
          <ixx>0.001</ixx>
          <ixy>0</ixy>
          <ixz>0</ixz>
          <iyy>0.03322</iyy>
          <iyz>0</iyz>
          <izz>0.001</izz>
        </inertia>
      </inertial>
      <collision name="wrist_link6_left_collision">
        <pose relative_to="">0 0 0 1.5708 -0 0</pose>
        <geometry>
          <cylinder>
            <length>0</length>
            <radius>0</radius>
          </cylinder>
        </geometry>
      </collision>
      <visual name="wrist_link6_left_visual">
        <pose relative_to="">0 0 0 1.5708 -0 0</pose>
        <geometry>
          <cylinder>
            <length>0</length>
            <radius>0</radius>
          </cylinder>
        </geometry>
      </visual>
    </link>
    <joint name="wrist_pitch_joint_left" type="revolute">
      <child>wrist_link6_left</child>
      <parent>fore_arm_left</parent>
      <axis>
        <xyz expressed_in="__model__">6e-06 -0.999999 0.001589</xyz>
        <limit>
          <lower>-0.95</lower>
          <upper>0.95</upper>
          <effort>1</effort>
          <velocity>1</velocity>
        </limit>
        <dynamics>
          <damping>0.35</damping>
          <friction>0.63</friction>
          <spring_reference>0</spring_reference>
          <spring_stiffness>0</spring_stiffness>
        </dynamics>
      </axis>
    </joint>
    <link name="hand_left">
      <pose relative_to="">-0.3365 0.219966 0.180847 -3.14 -7e-06 -3.14159</pose>
      <inertial>
        <pose relative_to="">0.047619 0 0 0 -0 0</pose>
        <mass>0.21</mass>
        <inertia>
          <ixx>0.0101</ixx>
          <ixy>0</ixy>
          <ixz>0</ixz>
          <iyy>0.0101006</iyy>
          <iyz>0</iyz>
          <izz>0.0623006</izz>
        </inertia>
      </inertial>
      <collision name="hand_left_collision">
        <pose relative_to="">0.048 0 0 0 -0 0</pose>
        <geometry>
          <box>
            <size>0.08 0.085 0.038</size>
          </box>
        </geometry>
      </collision>
      <collision name="hand_left_fixed_joint_lump__grippoint_left_collision_1">
        <pose relative_to="">0.04 0 0 0 -0 0</pose>
        <geometry>
          <box>
            <size>0 0 0</size>
          </box>
        </geometry>
      </collision>
      <visual name="hand_left_visual">
        <pose relative_to="">0.048 0 0 0 -0 0</pose>
        <geometry>
          <box>
            <size>0.08 0.085 0.038</size>
          </box>
        </geometry>
      </visual>
      <visual name="hand_left_fixed_joint_lump__grippoint_left_visual_1">
        <pose relative_to="">0.04 0 0 0 -0 0</pose>
        <geometry>
          <box>
            <size>0 0 0</size>
          </box>
        </geometry>
      </visual>
    </link>
    <joint name="wrist_yaw_joint_left" type="revolute">
      <child>hand_left</child>
      <parent>wrist_link6_left</parent>
      <axis>
        <xyz expressed_in="__model__">8.1e-05 0.017479 11</xyz>
        <limit>
          <lower>-0.61</lower>
          <upper>0.61</upper>
          <effort>1</effort>
          <velocity>1</velocity>
        </limit>
        <dynamics>
          <damping>0.3</damping>
          <friction>0.68</friction>
          <spring_reference>0</spring_reference>
          <spring_stiffness>0</spring_stiffness>
        </dynamics>
      </axis>
    </joint>
    <link name="finger1_left">
      <pose relative_to="">-0.4115 0.239965 0.180816 -2.03906 1.56902 -2.03905</pose>
      <inertial>
        <pose relative_to="">0 0 -0.045 0 -0 0</pose>
        <mass>0.02</mass>
        <inertia>
          <ixx>0.0110045</ixx>
          <ixy>0</ixy>
          <ixz>1.05879e-22</ixz>
          <iyy>0.0110045</iyy>
          <iyz>0</iyz>
          <izz>0.011</izz>
        </inertia>
      </inertial>
      <collision name="finger1_left_collision">
        <pose relative_to="">0 0 -0.03 0 -0 0</pose>
        <geometry>
          <box>
            <size>0.018 0.018 0.06</size>
          </box>
        </geometry>
      </collision>
      <collision name="finger1_left_fixed_joint_lump__finger1_phalanx_left_collision_1">
        <pose relative_to="">0 0 -0.06 0 1.57 0</pose>
        <geometry>
          <cylinder>
            <length>0.019</length>
            <radius>0.009</radius>
          </cylinder>
        </geometry>
      </collision>
      <visual name="finger1_left_visual">
        <pose relative_to="">0 0 -0.03 0 -0 0</pose>
        <geometry>
          <box>
            <size>0.018 0.018 0.06</size>
          </box>
        </geometry>
      </visual>
      <visual name="finger1_left_fixed_joint_lump__finger1_phalanx_left_visual_1">
        <pose relative_to="">0 0 -0.06 0 1.57 0</pose>
        <geometry>
          <cylinder>
            <length>0.019</length>
            <radius>0.009</radius>
          </cylinder>
        </geometry>
      </visual>
    </link>
    <joint name="finger1_joint_left" type="revolute">
      <child>finger1_left</child>
      <parent>hand_left</parent>
      <axis>
        <xyz expressed_in="__model__">-0.000804 -0.001589 -0.999998</xyz>
        <limit>
          <lower>-1.57</lower>
          <upper>1.57</upper>
          <effort>3</effort>
          <velocity>1</velocity>
        </limit>
        <dynamics>
          <damping>0.5</damping>
          <friction>1</friction>
          <spring_reference>0</spring_reference>
          <spring_stiffness>0</spring_stiffness>
        </dynamics>
      </axis>
    </joint>
    <link name="finger1_tip_left">
      <pose relative_to="">-0.4715 0.239965 0.180864 -2.03906 1.56902 -2.03905</pose>
      <inertial>
        <pose relative_to="">0 0 -0.045 0 -0 0</pose>
        <mass>0.02</mass>
        <inertia>
          <ixx>0.0013745</ixx>
          <ixy>0</ixy>
          <ixz>1.05879e-22</ixz>
          <iyy>0.0015245</iyy>
          <iyz>0</iyz>
          <izz>0.00152</izz>
        </inertia>
      </inertial>
      <collision name="finger1_tip_left_collision">
        <pose relative_to="">0 0 -0.03 0 -0 0</pose>
        <geometry>
          <box>
            <size>0.018 0.018 0.06</size>
          </box>
        </geometry>
      </collision>
      <collision name="finger1_tip_left_fixed_joint_lump__finger1_tip_phalanx_left_collision_1">
        <pose relative_to="">0 0 -0.06 0 1.57 0</pose>
        <geometry>
          <cylinder>
            <length>0.017</length>
            <radius>0.009</radius>
          </cylinder>
        </geometry>
      </collision>
      <visual name="finger1_tip_left_visual">
        <pose relative_to="">0 0 -0.03 0 -0 0</pose>
        <geometry>
          <box>
            <size>0.018 0.018 0.06</size>
          </box>
        </geometry>
      </visual>
      <visual name="finger1_tip_left_fixed_joint_lump__finger1_tip_phalanx_left_visual_1">
        <pose relative_to="">0 0 -0.06 0 1.57 0</pose>
        <geometry>
          <cylinder>
            <length>0.017</length>
            <radius>0.009</radius>
          </cylinder>
        </geometry>
      </visual>
    </link>
    <joint name="finger1_tip_joint_left" type="revolute">
      <child>finger1_tip_left</child>
      <parent>finger1_left</parent>
      <axis>
        <xyz expressed_in="__model__">-0.000804 -0.001589 -0.999998</xyz>
        <limit>
          <lower>-1.57</lower>
          <upper>1.57</upper>
          <effort>3</effort>
          <velocity>1</velocity>
        </limit>
        <dynamics>
          <damping>0.5</damping>
          <friction>1</friction>
          <spring_reference>0</spring_reference>
          <spring_stiffness>0</spring_stiffness>
        </dynamics>
      </axis>
    </joint>
    <link name="finger2_left">
      <pose relative_to="">-0.4115 0.199965 0.180879 -2.03906 1.56902 -2.03905</pose>
      <inertial>
        <pose relative_to="">0 0 -0.045 0 -0 0</pose>
        <mass>0.02</mass>
        <inertia>
          <ixx>0.0110045</ixx>
          <ixy>0</ixy>
          <ixz>1.05879e-22</ixz>
          <iyy>0.0110045</iyy>
          <iyz>0</iyz>
          <izz>0.011</izz>
        </inertia>
      </inertial>
      <collision name="finger2_left_collision">
        <pose relative_to="">0 0 -0.03 0 -0 0</pose>
        <geometry>
          <box>
            <size>0.018 0.018 0.06</size>
          </box>
        </geometry>
      </collision>
      <collision name="finger2_left_fixed_joint_lump__finger2_phalanx_left_collision_1">
        <pose relative_to="">0 0 -0.06 0 1.57 0</pose>
        <geometry>
          <cylinder>
            <length>0.019</length>
            <radius>0.009</radius>
          </cylinder>
        </geometry>
      </collision>
      <visual name="finger2_left_visual">
        <pose relative_to="">0 0 -0.03 0 -0 0</pose>
        <geometry>
          <box>
            <size>0.018 0.018 0.06</size>
          </box>
        </geometry>
      </visual>
      <visual name="finger2_left_fixed_joint_lump__finger2_phalanx_left_visual_1">
        <pose relative_to="">0 0 -0.06 0 1.57 0</pose>
        <geometry>
          <cylinder>
            <length>0.019</length>
            <radius>0.009</radius>
          </cylinder>
        </geometry>
      </visual>
    </link>
    <joint name="finger2_joint_left" type="revolute">
      <child>finger2_left</child>
      <parent>hand_left</parent>
      <axis>
        <xyz expressed_in="__model__">0.000804 0.001589 0.999998</xyz>
        <limit>
          <lower>-1.57</lower>
          <upper>1.57</upper>
          <effort>3</effort>
          <velocity>1</velocity>
        </limit>
        <dynamics>
          <damping>0.5</damping>
          <friction>1</friction>
          <spring_reference>0</spring_reference>
          <spring_stiffness>0</spring_stiffness>
        </dynamics>
      </axis>
    </joint>
    <link name="finger2_tip_left">
      <pose relative_to="">-0.4715 0.199965 0.180927 -2.03906 1.56902 -2.03905</pose>
      <inertial>
        <pose relative_to="">0 0 -0.045 0 -0 0</pose>
        <mass>0.02</mass>
        <inertia>
          <ixx>0.0013745</ixx>
          <ixy>0</ixy>
          <ixz>1.05879e-22</ixz>
          <iyy>0.0015245</iyy>
          <iyz>0</iyz>
          <izz>0.00152</izz>
        </inertia>
      </inertial>
      <collision name="finger2_tip_left_collision">
        <pose relative_to="">0 0 -0.03 0 -0 0</pose>
        <geometry>
          <box>
            <size>0.018 0.018 0.06</size>
          </box>
        </geometry>
      </collision>
      <collision name="finger2_tip_left_fixed_joint_lump__finger2_tip_phalanx_left_collision_1">
        <pose relative_to="">0 0 -0.06 0 1.57 0</pose>
        <geometry>
          <cylinder>
            <length>0.017</length>
            <radius>0.009</radius>
          </cylinder>
        </geometry>
      </collision>
      <visual name="finger2_tip_left_visual">
        <pose relative_to="">0 0 -0.03 0 -0 0</pose>
        <geometry>
          <box>
            <size>0.018 0.018 0.06</size>
          </box>
        </geometry>
      </visual>
      <visual name="finger2_tip_left_fixed_joint_lump__finger2_tip_phalanx_left_visual_1">
        <pose relative_to="">0 0 -0.06 0 1.57 0</pose>
        <geometry>
          <cylinder>
            <length>0.017</length>
            <radius>0.009</radius>
          </cylinder>
        </geometry>
      </visual>
    </link>
    <joint name="finger2_tip_joint_left" type="revolute">
      <child>finger2_tip_left</child>
      <parent>finger2_left</parent>
      <axis>
        <xyz expressed_in="__model__">0.000804 0.001589 0.999998</xyz>
        <limit>
          <lower>-1.57</lower>
          <upper>1.57</upper>
          <effort>3</effort>
          <velocity>1</velocity>
        </limit>
        <dynamics>
          <damping>0.5</damping>
          <friction>1</friction>
          <spring_reference>0</spring_reference>
          <spring_stiffness>0</spring_stiffness>
        </dynamics>
      </axis>
    </joint>
    <link name="shoulder_link1_right">
      <pose relative_to="">0.263501 -0.219999 0.200845 -0.002309 1.5692 -1.5731</pose>
      <inertial>
        <pose relative_to="">0 0 0 0 -0 0</pose>
        <mass>0.25</mass>
        <inertia>
          <ixx>6</ixx>
          <ixy>0</ixy>
          <ixz>0</ixz>
          <iyy>0.01</iyy>
          <iyz>0</iyz>
          <izz>0.01</izz>
        </inertia>
      </inertial>
      <collision name="shoulder_link1_right_collision">
        <pose relative_to="">0 0 0.0525 0 -0 0</pose>
        <geometry>
          <cylinder>
            <length>0.015</length>
            <radius>0.045</radius>
          </cylinder>
        </geometry>
      </collision>
      <visual name="shoulder_link1_right_visual">
        <pose relative_to="">0 0 0.0525 0 -0 0</pose>
        <geometry>
          <cylinder>
            <length>0.015</length>
            <radius>0.045</radius>
          </cylinder>
        </geometry>
      </visual>
    </link>
    <joint name="shoulder_yaw_joint_right" type="revolute">
      <child>shoulder_link1_right</child>
      <parent>trunk</parent>
      <axis>
        <xyz expressed_in="__model__">-4e-06 -0.001593 -0.999999</xyz>
        <limit>
          <lower>-1.57</lower>
          <upper>0</upper>
          <effort>13.4</effort>
          <velocity>1</velocity>
        </limit>
        <dynamics>
          <damping>4</damping>
          <friction>4.87</friction>
          <spring_reference>0</spring_reference>
          <spring_stiffness>0</spring_stiffness>
        </dynamics>
      </axis>
    </joint>
    <link name="shoulder_link2_right">
      <pose relative_to="">0.263501 -0.219999 0.200845 -1.57311 1.5692 -1.5731</pose>
      <inertial>
        <pose relative_to="">0 0 0 0 -0 0</pose>
        <mass>0.15</mass>
        <inertia>
          <ixx>0.01</ixx>
          <ixy>0</ixy>
          <ixz>0</ixz>
          <iyy>4.04</iyy>
          <iyz>0</iyz>
          <izz>0.001</izz>
        </inertia>
      </inertial>
      <collision name="shoulder_link2_right_collision">
        <pose relative_to="">0 -0.06 -0.05 0 -0 0</pose>
        <geometry>
          <box>
            <size>0.035 0.01 0.1</size>
          </box>
        </geometry>
      </collision>
      <visual name="shoulder_link2_right_visual">
        <pose relative_to="">0 -0.06 -0.05 0 -0 0</pose>
        <geometry>
          <box>
            <size>0.035 0.01 0.1</size>
          </box>
        </geometry>
      </visual>
    </link>
    <joint name="shoulder_pitch_joint_right" type="revolute">
      <child>shoulder_link2_right</child>
      <parent>shoulder_link1_right</parent>
      <axis>
        <xyz expressed_in="__model__">1e-05 -0.999999 0.001593</xyz>
        <limit>
          <lower>-1.57</lower>
          <upper>1.57</upper>
          <effort>13.4</effort>
          <velocity>1</velocity>
        </limit>
        <dynamics>
          <damping>4</damping>
          <friction>6.06</friction>
          <spring_reference>0</spring_reference>
          <spring_stiffness>0</spring_stiffness>
        </dynamics>
      </axis>
    </joint>
    <link name="upper_arm_right">
      <pose relative_to="">0.263501 -0.219999 0.200845 -0.002309 1.5692 -1.5731</pose>
      <inertial>
        <pose relative_to="">0 -0.2 0 0 -0 0</pose>
        <mass>2.95</mass>
        <inertia>
          <ixx>0.027</ixx>
          <ixy>0</ixy>
          <ixz>0</ixz>
          <iyy>0.45993</iyy>
          <iyz>0</iyz>
          <izz>0.004</izz>
        </inertia>
      </inertial>
      <collision name="upper_arm_right_collision">
        <pose relative_to="">-0.00959 -0.19131 -1e-05 0 -0 3.1415</pose>
        <geometry>
          <mesh>
            <scale>0.0004 0.0004 0.0004</scale>
            <uri>model://sergio_description/media/meshes/upperarmtextured.dae</uri>
          </mesh>
        </geometry>
      </collision>
      <visual name="upper_arm_right_visual">
        <pose relative_to="">-0.00959 -0.19131 -1e-05 0 -0 3.1415</pose>
        <geometry>
          <mesh>
            <scale>0.0004 0.0004 0.0004</scale>
            <uri>model://sergio_description/media/meshes/upperarmtextured.dae</uri>
          </mesh>
        </geometry>
      </visual>
    </link>
    <joint name="shoulder_roll_joint_right" type="revolute">
      <child>upper_arm_right</child>
      <parent>shoulder_link2_right</parent>
      <axis>
        <xyz expressed_in="__model__">1 6e-06 -4e-06</xyz>
        <limit>
          <lower>-1.57</lower>
          <upper>1.57</upper>
          <effort>9.8</effort>
          <velocity>1</velocity>
        </limit>
        <dynamics>
          <damping>3.8</damping>
          <friction>2.216</friction>
          <spring_reference>0</spring_reference>
          <spring_stiffness>0</spring_stiffness>
        </dynamics>
      </axis>
    </joint>
    <link name="elbow_link4_right">
      <pose relative_to="">-0.056499 -0.220017 0.190846 -1.57311 1.5692 -1.5731</pose>
      <inertial>
        <pose relative_to="">0 0 0 0 -0 0</pose>
        <mass>0.1</mass>
        <inertia>
          <ixx>0.001</ixx>
          <ixy>0</ixy>
          <ixz>0</ixz>
          <iyy>0.6</iyy>
          <iyz>0</iyz>
          <izz>0.001</izz>
        </inertia>
      </inertial>
      <collision name="elbow_link4_right_collision">
        <pose relative_to="">0 0 0 0 -0 0</pose>
        <geometry>
          <cylinder>
            <length>0</length>
            <radius>0</radius>
          </cylinder>
        </geometry>
      </collision>
      <visual name="elbow_link4_right_visual">
        <pose relative_to="">0 0 0 0 -0 0</pose>
        <geometry>
          <cylinder>
            <length>0</length>
            <radius>0</radius>
          </cylinder>
        </geometry>
      </visual>
    </link>
    <joint name="elbow_pitch_joint_right" type="revolute">
      <child>elbow_link4_right</child>
      <parent>upper_arm_right</parent>
      <axis>
        <xyz expressed_in="__model__">1e-05 -0.999999 0.001593</xyz>
        <limit>
          <lower>0</lower>
          <upper>2.23</upper>
          <effort>4.5</effort>
          <velocity>1</velocity>
        </limit>
        <dynamics>
          <damping>3</damping>
          <friction>1.18</friction>
          <spring_reference>0</spring_reference>
          <spring_stiffness>0</spring_stiffness>
        </dynamics>
      </axis>
    </joint>
    <link name="fore_arm_right">
      <pose relative_to="">-0.056499 -0.220017 0.190846 -0.002309 1.5692 -1.5731</pose>
      <inertial>
        <pose relative_to="">0 -0.14 0 0 -0 0</pose>
        <mass>0.85</mass>
        <inertia>
          <ixx>0.001</ixx>
          <ixy>0</ixy>
          <ixz>0</ixz>
          <iyy>0.5</iyy>
          <iyz>0</iyz>
          <izz>0.001</izz>
        </inertia>
      </inertial>
      <collision name="fore_arm_right_collision">
        <pose relative_to="">0.00425 -0.14868 0.00547 3.14159 -1.57079 3.14159</pose>
        <geometry>
          <mesh>
            <scale>0.0004 0.0004 0.0004</scale>
            <uri>model://sergio_description/media/meshes/forearmtextured.dae</uri>
          </mesh>
        </geometry>
      </collision>
      <visual name="fore_arm_right_visual">
        <pose relative_to="">0.00425 -0.14868 0.00547 3.14159 -1.57079 3.14159</pose>
        <geometry>
          <mesh>
            <scale>0.0004 0.0004 0.0004</scale>
            <uri>model://sergio_description/media/meshes/forearmtextured.dae</uri>
          </mesh>
        </geometry>
      </visual>
    </link>
    <joint name="elbow_roll_joint_right" type="revolute">
      <child>fore_arm_right</child>
      <parent>elbow_link4_right</parent>
      <axis>
        <xyz expressed_in="__model__">1 6e-06 -4e-06</xyz>
        <limit>
          <lower>-1.83</lower>
          <upper>1.83</upper>
          <effort>4.5</effort>
          <velocity>1</velocity>
        </limit>
        <dynamics>
          <damping>3.5</damping>
          <friction>1.35</friction>
          <spring_reference>0</spring_reference>
          <spring_stiffness>0</spring_stiffness>
        </dynamics>
      </axis>
    </joint>
    <link name="wrist_link6_right">
      <pose relative_to="">-0.336499 -0.220034 0.180847 -3.14 -7e-06 -3.14159</pose>
      <inertial>
        <pose relative_to="">0 0 0 0 -0 0</pose>
        <mass>0.01</mass>
        <inertia>
          <ixx>0.001</ixx>
          <ixy>0</ixy>
          <ixz>0</ixz>
          <iyy>0.03322</iyy>
          <iyz>0</iyz>
          <izz>0.001</izz>
        </inertia>
      </inertial>
      <collision name="wrist_link6_right_collision">
        <pose relative_to="">0 0 0 1.5708 -0 0</pose>
        <geometry>
          <cylinder>
            <length>0</length>
            <radius>0</radius>
          </cylinder>
        </geometry>
      </collision>
      <visual name="wrist_link6_right_visual">
        <pose relative_to="">0 0 0 1.5708 -0 0</pose>
        <geometry>
          <cylinder>
            <length>0</length>
            <radius>0</radius>
          </cylinder>
        </geometry>
      </visual>
    </link>
    <joint name="wrist_pitch_joint_right" type="revolute">
      <child>wrist_link6_right</child>
      <parent>fore_arm_right</parent>
      <axis>
        <xyz expressed_in="__model__">6e-06 -0.999999 0.001589</xyz>
        <limit>
          <lower>-0.95</lower>
          <upper>0.95</upper>
          <effort>1</effort>
          <velocity>1</velocity>
        </limit>
        <dynamics>
          <damping>0.35</damping>
          <friction>0.63</friction>
          <spring_reference>0</spring_reference>
          <spring_stiffness>0</spring_stiffness>
        </dynamics>
      </axis>
    </joint>
    <link name="hand_right">
      <pose relative_to="">-0.336499 -0.220034 0.180847 -3.14 -7e-06 -3.14159</pose>
      <inertial>
        <pose relative_to="">0.047619 0 0 0 -0 0</pose>
        <mass>0.21</mass>
        <inertia>
          <ixx>0.0101</ixx>
          <ixy>0</ixy>
          <ixz>0</ixz>
          <iyy>0.0101006</iyy>
          <iyz>0</iyz>
          <izz>0.0623006</izz>
        </inertia>
      </inertial>
      <collision name="hand_right_collision">
        <pose relative_to="">0.048 0 0 0 -0 0</pose>
        <geometry>
          <box>
            <size>0.08 0.085 0.038</size>
          </box>
        </geometry>
      </collision>
      <collision name="hand_right_fixed_joint_lump__grippoint_right_collision_1">
        <pose relative_to="">0.04 0 0 0 -0 0</pose>
        <geometry>
          <box>
            <size>0 0 0</size>
          </box>
        </geometry>
      </collision>
      <visual name="hand_right_visual">
        <pose relative_to="">0.048 0 0 0 -0 0</pose>
        <geometry>
          <box>
            <size>0.08 0.085 0.038</size>
          </box>
        </geometry>
      </visual>
      <visual name="hand_right_fixed_joint_lump__grippoint_right_visual_1">
        <pose relative_to="">0.04 0 0 0 -0 0</pose>
        <geometry>
          <box>
            <size>0 0 0</size>
          </box>
        </geometry>
      </visual>
    </link>
    <joint name="wrist_yaw_joint_right" type="revolute">
      <child>hand_right</child>
      <parent>wrist_link6_right</parent>
      <axis>
        <xyz expressed_in="__model__">-8.1e-05 -0.017479 -11</xyz>
        <limit>
          <lower>-0.61</lower>
          <upper>0.61</upper>
          <effort>1</effort>
          <velocity>1</velocity>
        </limit>
        <dynamics>
          <damping>0.3</damping>
          <friction>0.68</friction>
          <spring_reference>0</spring_reference>
          <spring_stiffness>0</spring_stiffness>
        </dynamics>
      </axis>
    </joint>
    <link name="finger1_right">
      <pose relative_to="">-0.411499 -0.200035 0.180816 -2.03906 1.56902 -2.03905</pose>
      <inertial>
        <pose relative_to="">0 0 -0.045 0 -0 0</pose>
        <mass>0.02</mass>
        <inertia>
          <ixx>0.0110045</ixx>
          <ixy>0</ixy>
          <ixz>1.05879e-22</ixz>
          <iyy>0.0110045</iyy>
          <iyz>0</iyz>
          <izz>0.011</izz>
        </inertia>
      </inertial>
      <collision name="finger1_right_collision">
        <pose relative_to="">0 0 -0.03 0 -0 0</pose>
        <geometry>
          <box>
            <size>0.018 0.018 0.06</size>
          </box>
        </geometry>
      </collision>
      <collision name="finger1_right_fixed_joint_lump__finger1_phalanx_right_collision_1">
        <pose relative_to="">0 0 -0.06 0 1.57 0</pose>
        <geometry>
          <cylinder>
            <length>0.019</length>
            <radius>0.009</radius>
          </cylinder>
        </geometry>
      </collision>
      <visual name="finger1_right_visual">
        <pose relative_to="">0 0 -0.03 0 -0 0</pose>
        <geometry>
          <box>
            <size>0.018 0.018 0.06</size>
          </box>
        </geometry>
      </visual>
      <visual name="finger1_right_fixed_joint_lump__finger1_phalanx_right_visual_1">
        <pose relative_to="">0 0 -0.06 0 1.57 0</pose>
        <geometry>
          <cylinder>
            <length>0.019</length>
            <radius>0.009</radius>
          </cylinder>
        </geometry>
      </visual>
    </link>
    <joint name="finger1_joint_right" type="revolute">
      <child>finger1_right</child>
      <parent>hand_right</parent>
      <axis>
        <xyz expressed_in="__model__">-0.000804 -0.001589 -0.999998</xyz>
        <limit>
          <lower>-1.57</lower>
          <upper>1.57</upper>
          <effort>3</effort>
          <velocity>1</velocity>
        </limit>
        <dynamics>
          <damping>0.5</damping>
          <friction>1</friction>
          <spring_reference>0</spring_reference>
          <spring_stiffness>0</spring_stiffness>
        </dynamics>
      </axis>
    </joint>
    <link name="finger1_tip_right">
      <pose relative_to="">-0.471499 -0.200035 0.180864 -2.03906 1.56902 -2.03905</pose>
      <inertial>
        <pose relative_to="">0 0 -0.045 0 -0 0</pose>
        <mass>0.02</mass>
        <inertia>
          <ixx>0.0013745</ixx>
          <ixy>0</ixy>
          <ixz>1.05879e-22</ixz>
          <iyy>0.0015245</iyy>
          <iyz>0</iyz>
          <izz>0.00152</izz>
        </inertia>
      </inertial>
      <collision name="finger1_tip_right_collision">
        <pose relative_to="">0 0 -0.03 0 -0 0</pose>
        <geometry>
          <box>
            <size>0.018 0.018 0.06</size>
          </box>
        </geometry>
      </collision>
      <collision name="finger1_tip_right_fixed_joint_lump__finger1_tip_phalanx_right_collision_1">
        <pose relative_to="">0 0 -0.06 0 1.57 0</pose>
        <geometry>
          <cylinder>
            <length>0.017</length>
            <radius>0.009</radius>
          </cylinder>
        </geometry>
      </collision>
      <visual name="finger1_tip_right_visual">
        <pose relative_to="">0 0 -0.03 0 -0 0</pose>
        <geometry>
          <box>
            <size>0.018 0.018 0.06</size>
          </box>
        </geometry>
      </visual>
      <visual name="finger1_tip_right_fixed_joint_lump__finger1_tip_phalanx_right_visual_1">
        <pose relative_to="">0 0 -0.06 0 1.57 0</pose>
        <geometry>
          <cylinder>
            <length>0.017</length>
            <radius>0.009</radius>
          </cylinder>
        </geometry>
      </visual>
    </link>
    <joint name="finger1_tip_joint_right" type="revolute">
      <child>finger1_tip_right</child>
      <parent>finger1_right</parent>
      <axis>
        <xyz expressed_in="__model__">-0.000804 -0.001589 -0.999998</xyz>
        <limit>
          <lower>-1.57</lower>
          <upper>1.57</upper>
          <effort>3</effort>
          <velocity>1</velocity>
        </limit>
        <dynamics>
          <damping>0.5</damping>
          <friction>1</friction>
          <spring_reference>0</spring_reference>
          <spring_stiffness>0</spring_stiffness>
        </dynamics>
      </axis>
    </joint>
    <link name="finger2_right">
      <pose relative_to="">-0.411499 -0.240035 0.180879 -2.03906 1.56902 -2.03905</pose>
      <inertial>
        <pose relative_to="">0 0 -0.045 0 -0 0</pose>
        <mass>0.02</mass>
        <inertia>
          <ixx>0.0110045</ixx>
          <ixy>0</ixy>
          <ixz>1.05879e-22</ixz>
          <iyy>0.0110045</iyy>
          <iyz>0</iyz>
          <izz>0.011</izz>
        </inertia>
      </inertial>
      <collision name="finger2_right_collision">
        <pose relative_to="">0 0 -0.03 0 -0 0</pose>
        <geometry>
          <box>
            <size>0.018 0.018 0.06</size>
          </box>
        </geometry>
      </collision>
      <collision name="finger2_right_fixed_joint_lump__finger2_phalanx_right_collision_1">
        <pose relative_to="">0 0 -0.06 0 1.57 0</pose>
        <geometry>
          <cylinder>
            <length>0.019</length>
            <radius>0.009</radius>
          </cylinder>
        </geometry>
      </collision>
      <visual name="finger2_right_visual">
        <pose relative_to="">0 0 -0.03 0 -0 0</pose>
        <geometry>
          <box>
            <size>0.018 0.018 0.06</size>
          </box>
        </geometry>
      </visual>
      <visual name="finger2_right_fixed_joint_lump__finger2_phalanx_right_visual_1">
        <pose relative_to="">0 0 -0.06 0 1.57 0</pose>
        <geometry>
          <cylinder>
            <length>0.019</length>
            <radius>0.009</radius>
          </cylinder>
        </geometry>
      </visual>
    </link>
    <joint name="finger2_joint_right" type="revolute">
      <child>finger2_right</child>
      <parent>hand_right</parent>
      <axis>
        <xyz expressed_in="__model__">0.000804 0.001589 0.999998</xyz>
        <limit>
          <lower>-1.57</lower>
          <upper>1.57</upper>
          <effort>3</effort>
          <velocity>1</velocity>
        </limit>
        <dynamics>
          <damping>0.5</damping>
          <friction>1</friction>
          <spring_reference>0</spring_reference>
          <spring_stiffness>0</spring_stiffness>
        </dynamics>
      </axis>
    </joint>
    <link name="finger2_tip_right">
      <pose relative_to="">-0.471499 -0.240035 0.180927 -2.03906 1.56902 -2.03905</pose>
      <inertial>
        <pose relative_to="">0 0 -0.045 0 -0 0</pose>
        <mass>0.02</mass>
        <inertia>
          <ixx>0.0013745</ixx>
          <ixy>0</ixy>
          <ixz>1.05879e-22</ixz>
          <iyy>0.0015245</iyy>
          <iyz>0</iyz>
          <izz>0.00152</izz>
        </inertia>
      </inertial>
      <collision name="finger2_tip_right_collision">
        <pose relative_to="">0 0 -0.03 0 -0 0</pose>
        <geometry>
          <box>
            <size>0.018 0.018 0.06</size>
          </box>
        </geometry>
      </collision>
      <collision name="finger2_tip_right_fixed_joint_lump__finger2_tip_phalanx_right_collision_1">
        <pose relative_to="">0 0 -0.06 0 1.57 0</pose>
        <geometry>
          <cylinder>
            <length>0.017</length>
            <radius>0.009</radius>
          </cylinder>
        </geometry>
      </collision>
      <visual name="finger2_tip_right_visual">
        <pose relative_to="">0 0 -0.03 0 -0 0</pose>
        <geometry>
          <box>
            <size>0.018 0.018 0.06</size>
          </box>
        </geometry>
      </visual>
      <visual name="finger2_tip_right_fixed_joint_lump__finger2_tip_phalanx_right_visual_1">
        <pose relative_to="">0 0 -0.06 0 1.57 0</pose>
        <geometry>
          <cylinder>
            <length>0.017</length>
            <radius>0.009</radius>
          </cylinder>
        </geometry>
      </visual>
    </link>
    <joint name="finger2_tip_joint_right" type="revolute">
      <child>finger2_tip_right</child>
      <parent>finger2_right</parent>
      <axis>
        <xyz expressed_in="__model__">0.000804 0.001589 0.999998</xyz>
        <limit>
          <lower>-1.57</lower>
          <upper>1.57</upper>
          <effort>3</effort>
          <velocity>1</velocity>
        </limit>
        <dynamics>
          <damping>0.5</damping>
          <friction>1</friction>
          <spring_reference>0</spring_reference>
          <spring_stiffness>0</spring_stiffness>
        </dynamics>
    </axis>
    </joint>
  </model>
</sdf>
